Workbook

Sheet Sheet1
A1: mID | B1: Day | C1: Start Time | D1: End Time | E1: Volume Chamber | F1: Notes | G1: Modifiers
A2: VF1F | B2: 45718 | C2: 0.54166667 | D2: 0.55486111 | E2: 9541.6 | F2: Aeris | G2: au10 | H2: =MID(A2,2, 1) -> F | I2: =VLOOKUP(H2, $O$2:$P$6, 2, FALSE) -> 9541.6 | O2: F | P2: 9541.6
A3: VB2F | B3: 45718 | C3: 0.55486111 | D3: 0.56458333 | E3: 9541.6 | F3: Aeris | G3: au10 | H3: =MID(A3,2, 1) -> B | I3: =VLOOKUP(H3, $O$2:$P$6, 2, FALSE) -> 9541.6 | O3: B | P3: 9541.6
A4: VI3F | B4: 45718 | C4: 0.62152778 | D4: 0.62986111 | E4: 110200 | F4: Aeris | G4: au10 | H4: =MID(A4,2, 1) -> I | I4: =VLOOKUP(H4, $O$2:$P$6, 2, FALSE) -> 110200 | O4: I | P4: =50*58*38 -> 110200
A5: VS4F | B5: 45719 | C5: 0.52638889 | D5: 0.53333333 | E5: 265428 | F5: Aeris | G5: au10 | H5: =MID(A5,2, 1) -> S | I5: =VLOOKUP(H5, $O$2:$P$6, 2, FALSE) -> 265428 | O5: V | P5: =50*61*48 -> 146400
A6: VI5F | B6: 45719 | C6: 0.54236111 | D6: 0.54930556 | E6: 110200 | F6: Aeris | G6: au10 | H6: =MID(A6,2, 1) -> I | I6: =VLOOKUP(H6, $O$2:$P$6, 2, FALSE) -> 110200 | O6: S | P6: =73*101*36 -> 265428
A7: VS6F | B7: 45719 | C7: 0.72222222 | D7: 0.73055556 | E7: 265428 | F7: Aeris | G7: au10 | H7: =MID(A7,2, 1) -> S | I7: =VLOOKUP(H7, Sheet1!$O$2:$P$6, 2, FALSE) -> 265428
A8: VF7F | B8: 45719 | C8: 0.73958333 | D8: 0.74722222 | E8: 9541.6 | F8: Aeris | G8: au10 | H8: =MID(A8,2, 1) -> F | I8: =VLOOKUP(H8, Sheet1!$O$2:$P$6, 2, FALSE) -> 9541.6
A9: VV8F | B9: 45719 | C9: 0.71388889 | D9: 0.72152778 | E9: 146400 | F9: Aeris | G9: au10 | H9: =MID(A9,2, 1) -> V | I9: =VLOOKUP(H9, Sheet1!$O$2:$P$6, 2, FALSE) -> 146400
A10: VF9F | B10: 45720 | C10: 0.42222222 | D10: 0.42916667 | E10: 9541.6 | F10: Aeris | G10: au10 | H10: =MID(A10,2, 1) -> F | I10: =VLOOKUP(H10, Sheet1!$O$2:$P$6, 2, FALSE) -> 9541.6
A11: VB10F | B11: 45720 | C11: 0.40486111 | D11: 0.41180556 | E11: 9541.6 | F11: Aeris | G11: au10 | H11: =MID(A11,2, 1) -> B | I11: =VLOOKUP(H11, Sheet1!$O$2:$P$6, 2, FALSE) -> 9541.6
A12: VS11F | B12: 45720 | C12: 0.51666667 | D12: 0.52361111 | E12: 265428 | F12: Aeris | G12: au10 | H12: =MID(A12,2, 1) -> S | I12: =VLOOKUP(H12, Sheet1!$O$2:$P$6, 2, FALSE) -> 265428
A13: VS12F | B13: 45721 | C13: 0.52708333 | D13: 0.53402778 | E13: 265428 | F13: Aeris | G13: au10 | H13: =MID(A13,2, 1) -> S | I13: =VLOOKUP(H13, Sheet1!$O$2:$P$6, 2, FALSE) -> 265428
A14: VS13F | B14: 45721 | C14: 0.53680556 | D14: 0.54513889 | E14: 265428 | F14: Aeris | G14: au10 | H14: =MID(A14,2, 1) -> S | I14: =VLOOKUP(H14, Sheet1!$O$2:$P$6, 2, FALSE) -> 265428
A15: VB14F | B15: 45721 | C15: 0.55763889 | D15: 0.56527778 | E15: 9541.6 | F15: Aeris | G15: au10 | H15: =MID(A15,2, 1) -> B | I15: =VLOOKUP(H15, Sheet1!$O$2:$P$6, 2, FALSE) -> 9541.6
A16: VS15F | B16: 45721 | C16: 0.60138889 | D16: 0.60902778 | E16: 265428 | F16: Aeris | G16: au10 | H16: =MID(A16,2, 1) -> S | I16: =VLOOKUP(H16, Sheet1!$O$2:$P$6, 2, FALSE) -> 265428
A17: VI16F | B17: 45721 | C17: 0.62361111 | D17: 0.71458333 | E17: 110200 | F17: Aeris | G17: au10 | H17: =MID(A17,2, 1) -> I | I17: =VLOOKUP(H17, Sheet1!$O$2:$P$6, 2, FALSE) -> 110200
A18: VS17F | B18: 45721 | C18: 0.63819444 | D18: 0.64513889 | E18: 265428 | F18: Aeris | G18: au10 | H18: =MID(A18,2, 1) -> S | I18: =VLOOKUP(H18, Sheet1!$O$2:$P$6, 2, FALSE) -> 265428
... A47: VV49F | B47: 45726 | C47: 0.51597222 | D47: 0.52291667 | E47: 146400 | F47: Aeris | G47: au10 | H47: =MID(A47,2, 1) -> V | I47: =VLOOKUP(H47, Sheet1!$O$2:$P$6, 2, FALSE) -> 146400
A48: VB50F | B48: 45726 | C48: 0.53125 | D48: 0.53819444 | E48: 4770.8 | F48: Aeris | G48: au10 | H48: =MID(A48,2, 1) -> B | I48: =VLOOKUP(H48, Sheet1!$O$2:$P$6, 2, FALSE)/2 -> 4770.8
A49: VS51F | B49: 45726 | C49: 0.54791667 | D49: 0.55486111 | E49: 265428 | F49: Aeris | G49: au10 | H49: =MID(A49,2, 1) -> S | I49: =VLOOKUP(H49, Sheet1!$O$2:$P$6, 2, FALSE) -> 265428
A50: VV52F | B50: 45726 | C50: 0.55555556 | D50: 0.5625 | E50: 146400 | F50: Aeris | G50: au10 | H50: =MID(A50,2, 1) -> V | I50: =VLOOKUP(H50, Sheet1!$O$2:$P$6, 2, FALSE) -> 146400
A51: VB53O | B51: 45727 | C51: 0.35486111 | D51: 0.36180556 | E51: 4770.8 | F51: Aeris | G51: au10 | H51: =MID(A51,2, 1) -> B | I51: =VLOOKUP(H51, Sheet1!$O$2:$P$6, 2, FALSE)/2 -> 4770.8
A52: VB54O | B52: 45727 | C52: 0.375 | D52: 0.38194444 | E52: 9541.6 | F52: Aeris | G52: au10 | H52: =MID(A52,2, 1) -> B | I52: =VLOOKUP(H52, Sheet1!$O$2:$P$6, 2, FALSE) -> 9541.6
A53: VI55F | B53: 45727 | C53: 0.38819444 | D53: 0.39513889 | E53: 110200 | F53: Aeris | G53: au10 | H53: =MID(A53,2, 1) -> I | I53: =VLOOKUP(H53, Sheet1!$O$2:$P$6, 2, FALSE) -> 110200
A54: VF56O | B54: 45727 | C54: 0.48541667 | D54: 0.49236111 | E54: 4770.8 | F54: Aeris | G54: au10 | H54: =MID(A54,2, 1) -> F | I54: =VLOOKUP(H54, Sheet1!$O$2:$P$6, 2, FALSE)/2 -> 4770.8
A55: VB58F | B55: 45727 | C55: 0.71597222 | D55: 0.71736111 | E55: 4770.8 | F55: Aeris | G55: au10 | H55: =MID(A55,2, 1) -> B | I55: =VLOOKUP(H55, Sheet1!$O$2:$P$6, 2, FALSE)/2 -> 4770.8
A56: VS59F | B56: 45727 | C56: 0.75138889 | D56: 0.75347222 | E56: 265428 | F56: Aeris | G56: au10 | H56: =MID(A56,2, 1) -> S | I56: =VLOOKUP(H56, Sheet1!$O$2:$P$6, 2, FALSE) -> 265428
A57: VV60F | B57: 45727 | C57: 0.75138889 | D57: 0.75347222 | E57: 146400 | F57: Aeris | G57: au10 | H57: =MID(A57,2, 1) -> V | I57: =VLOOKUP(H57, Sheet1!$O$2:$P$6, 2, FALSE) -> 146400
A58: VB61F | B58: 45728 | C58: 0.37708333 | D58: 0.37847222 | E58: 9541.6 | F58: Aeris | G58: au10 | H58: =MID(A58,2, 1) -> B | I58: =VLOOKUP(H58, Sheet1!$O$2:$P$6, 2, FALSE) -> 9541.6
A59: VS62F | B59: 45728 | C59: 0.50555556 | D59: 0.50694444 | E59: 265428 | F59: Aeris | G59: au10 | H59: =MID(A59,2, 1) -> S | I59: =VLOOKUP(H59, Sheet1!$O$2:$P$6, 2, FALSE) -> 265428
A60: VV63F | B60: 45728 | C60: 0.50555556 | D60: 0.50694444 | E60: 146400 | F60: Aeris | G60: au10 | H60: =MID(A60,2, 1) -> V | I60: =VLOOKUP(H60, Sheet1!$O$2:$P$6, 2, FALSE) -> 146400
A61: VS64F | B61: 45728 | C61: 0.52986111 | D61: 0.53125 | E61: 265428 | F61: Aeris | G61: au10 | H61: =MID(A61,2, 1) -> S | I61: =VLOOKUP(H61, Sheet1!$O$2:$P$6, 2, FALSE) -> 265428
A62: VV65F | B62: 45728 | C62: 0.52986111 | D62: 0.53125 | E62: 146400 | F62: Aeris | G62: au10 | H62: =MID(A62,2, 1) -> V | I62: =VLOOKUP(H62, Sheet1!$O$2:$P$6, 2, FALSE) -> 146400
A63: VI66F | B63: 45728 | C63: 0.52986111 | D63: 0.53125 | E63: 110200 | F63: Aeris | G63: au10 | H63: =MID(A63,2, 1) -> I | I63: =VLOOKUP(H63, Sheet1!$O$2:$P$6, 2, FALSE) -> 110200
A64: VB67F | B64: 45728 | C64: 0.56944444 | D64: 0.57638889 | E64: 1468800 | F64: Aeris | G64: au10 | H64: =MID(A64,2, 1) -> B | I64: =72*204*100 -> 1468800
A65: VI68F | B65: 45729 | C65: 0.36180556 | D65: 0.37013889 | E65: 110200 | F65: Aeris | G65: au10 | H65: =MID(A65,2, 1) -> I | I65: =VLOOKUP(H65, Sheet1!$O$2:$P$6, 2, FALSE) -> 110200
A66: VS69F | B66: 45730 | C66: 0.39513889 | D66: 0.40208333 | E66: 265428 | F66: Aeris | G66: au10 | H66: =MID(A66,2, 1) -> S | I66: =VLOOKUP(H66, Sheet1!$O$2:$P$6, 2, FALSE) -> 265428
A67: VV70F | B67: 45730 | C67: 0.40416667 | D67: 0.4125 | E67: 146400 | F67: Aeris | G67: au10 | H67: =MID(A67,2, 1) -> V | I67: =VLOOKUP(H67, Sheet1!$O$2:$P$6, 2, FALSE) -> 146400
A68: VB71O | B68: 45730 | C68: 0.42222222 | D68: 0.42916667 | E68: 1468800 | F68: Aeris | G68: au10 | H68: =MID(A68,2, 1) -> B | I68: =72*204*100 -> 1468800
...

Sheet Sheet2
